<?xml version="1.0" ?>
<!-- =================================================================================== -->
<!-- |    This document was autogenerated by xacro from /home/samak/ROS_Workspaces/VRX/src/SINGABOAT-VRX/vrx/wamv_gazebo/urdf/wamv_gazebo.urdf.xacro | -->
<!-- |    EDITING THIS FILE BY HAND IS NOT RECOMMENDED                                 | -->
<!-- =================================================================================== -->
<!-- Basic WAM-V with gazebo plugins for dynamics -->
<robot name="WAM-V">
  <link name="wamv/left_battery_link">
    <visual name="left_battery_visual">
      <origin rpy="0 0 0" xyz="0 -1.03 -.45"/>
      <geometry>
        <mesh filename="package://vrx_gazebo/models/battery/mesh/battery.dae"/>
      </geometry>
    </visual>
    <collision name="left_battery_collision">
      <origin rpy="0 0 0" xyz="0 0 .15"/>
      <geometry>
        <box size=".6 .4 .31"/>
      </geometry>
    </collision>
    <inertial>
      <origin rpy=" 0 0 0" xyz="0 0 .15"/>
      <mass value="23.5"/>
      <inertia ixx="0.5015291666666667" ixy="0" ixz="0" iyy="0.8931958333333333" iyz="0" izz="1.0183333333333333"/>
    </inertial>
  </link>
  <joint name="wamv/left_chasis_battery_joint" type="fixed">
    <origin rpy="0 0 0" xyz="0 1 0.45"/>
    <parent link="wamv/base_link"/>
    <child link="wamv/left_battery_link"/>
  </joint>
  <link name="wamv/right_battery_link">
    <visual name="right_battery_visual">
      <origin rpy="0 0 0" xyz="0 -1.03 -.45"/>
      <geometry>
        <mesh filename="package://vrx_gazebo/models/battery/mesh/battery.dae"/>
      </geometry>
    </visual>
    <collision name="right_battery_collision">
      <origin rpy="0 0 0" xyz="0 0 .15"/>
      <geometry>
        <box size=".6 .4 .31"/>
      </geometry>
    </collision>
    <inertial>
      <origin rpy=" 0 0 0" xyz="0 0 .15"/>
      <mass value="23.5"/>
      <inertia ixx="0.5015291666666667" ixy="0" ixz="0" iyy="0.8931958333333333" iyz="0" izz="1.0183333333333333"/>
    </inertial>
  </link>
  <joint name="wamv/right_chasis_battery_joint" type="fixed">
    <origin rpy="0 0 0" xyz="0 -1 0.45"/>
    <parent link="wamv/base_link"/>
    <child link="wamv/right_battery_link"/>
  </joint>
  <link name="wamv/base_link">
  </link>
  <joint name="wamv/dummy_joint" type="fixed">
    <parent link="wamv/base_link"/>
    <child link="wamv/dummy_link"/>
  </joint>
  <!-- Basic model of the 16' WAM-V USV -->
  <link name="wamv/dummy_link">
    <visual>
      <geometry>
        <mesh filename="package://wamv_description/models/WAM-V-Base/mesh/WAM-V-Base.dae"/>
      </geometry>
    </visual>
    <!-- Main float -->
    <collision name="left_float">
      <origin rpy="0 1.57 0" xyz="-0.4 1.03 0.2"/>
      <geometry>
        <cylinder length="4" radius="0.2"/>
      </geometry>
    </collision>
    <collision name="left_mid_float">
      <origin rpy="0 1.38 0" xyz="1.85 1.03 0.3"/>
      <geometry>
        <cylinder length="0.5" radius="0.17"/>
      </geometry>
    </collision>
    <collision name="left_front_float">
      <origin rpy="0 1.3 0" xyz="2.3 1.03 0.4"/>
      <geometry>
        <cylinder length="0.45" radius="0.12"/>
      </geometry>
    </collision>
    <!-- Front beam -->
    <collision name="front_left_beam_lower">
      <origin rpy="0.78 0 0" xyz="0.9 0.85 1"/>
      <geometry>
        <cylinder length="0.5" radius="0.04"/>
      </geometry>
    </collision>
    <collision name="front_left_beam_upper">
      <origin rpy="1.35 0 0" xyz="0.9 0.6 1.18"/>
      <geometry>
        <cylinder length="0.2" radius="0.04"/>
      </geometry>
    </collision>
    <!-- Mid beam -->
    <collision name="mid_left_beam_lower">
      <origin rpy="0.1 0.25 0" xyz="-0.65 0.99 0.7"/>
      <geometry>
        <cylinder length="0.45" radius="0.03"/>
      </geometry>
    </collision>
    <collision name="mid_left_beam_medium">
      <origin rpy="0.75 0.25 0" xyz="-0.57 0.87 1.05"/>
      <geometry>
        <cylinder length="0.32" radius="0.03"/>
      </geometry>
    </collision>
    <collision name="mid_left_beam_upper">
      <origin rpy="1.35 0.25 0" xyz="-0.55 0.65 1.17"/>
      <geometry>
        <cylinder length="0.3" radius="0.03"/>
      </geometry>
    </collision>
    <!-- Rear beam -->
    <collision name="rear_left_beam_lower">
      <origin rpy="0 -0.15 0" xyz="-0.74 1.03 0.7"/>
      <geometry>
        <cylinder length="0.45" radius="0.03"/>
      </geometry>
    </collision>
    <collision name="rear_left_beam_medium">
      <origin rpy="0.75 -0.15 0" xyz="-0.79 0.91 1.05"/>
      <geometry>
        <cylinder length="0.32" radius="0.03"/>
      </geometry>
    </collision>
    <collision name="rear_left_beam_upper">
      <origin rpy="1.45 -0.15 0" xyz="-0.81 0.67 1.18"/>
      <geometry>
        <cylinder length="0.3" radius="0.03"/>
      </geometry>
    </collision>
    <!-- Joint -->
    <collision name="left_joint">
      <origin rpy="0 -0.6 0" xyz="0.58 1.03 0.6"/>
      <geometry>
        <box size="0.65 0.2 0.1"/>
      </geometry>
    </collision>
    <!-- Main float -->
    <collision name="right_float">
      <origin rpy="0 1.57 0" xyz="-0.4 -1.03 0.2"/>
      <geometry>
        <cylinder length="4" radius="0.2"/>
      </geometry>
    </collision>
    <collision name="right_mid_float">
      <origin rpy="0 1.38 0" xyz="1.85 -1.03 0.3"/>
      <geometry>
        <cylinder length="0.5" radius="0.17"/>
      </geometry>
    </collision>
    <collision name="right_front_float">
      <origin rpy="0 1.3 0" xyz="2.3 -1.03 0.4"/>
      <geometry>
        <cylinder length="0.45" radius="0.12"/>
      </geometry>
    </collision>
    <!-- Front beam -->
    <collision name="front_right_beam_lower">
      <origin rpy="-0.78 0 0" xyz="0.9 -0.85 1"/>
      <geometry>
        <cylinder length="0.5" radius="0.04"/>
      </geometry>
    </collision>
    <collision name="front_right_beam_upper">
      <origin rpy="-1.35 0 0" xyz="0.9 -0.6 1.18"/>
      <geometry>
        <cylinder length="0.2" radius="0.04"/>
      </geometry>
    </collision>
    <!-- Mid beam -->
    <collision name="mid_right_beam_lower">
      <origin rpy="-0.1 0.25 0" xyz="-0.65 -0.99 0.7"/>
      <geometry>
        <cylinder length="0.45" radius="0.03"/>
      </geometry>
    </collision>
    <collision name="mid_right_beam_medium">
      <origin rpy="-0.75 0.25 0" xyz="-0.57 -0.87 1.05"/>
      <geometry>
        <cylinder length="0.32" radius="0.03"/>
      </geometry>
    </collision>
    <collision name="mid_right_beam_upper">
      <origin rpy="-1.35 0.25 0" xyz="-0.55 -0.65 1.17"/>
      <geometry>
        <cylinder length="0.3" radius="0.03"/>
      </geometry>
    </collision>
    <!-- Rear beam -->
    <collision name="rear_right_beam_lower">
      <origin rpy="0 -0.15 0" xyz="-0.74 -1.03 0.7"/>
      <geometry>
        <cylinder length="0.45" radius="0.03"/>
      </geometry>
    </collision>
    <collision name="rear_right_beam_medium">
      <origin rpy="-0.75 -0.15 0" xyz="-0.79 -0.91 1.05"/>
      <geometry>
        <cylinder length="0.32" radius="0.03"/>
      </geometry>
    </collision>
    <collision name="rear_right_beam_upper">
      <origin rpy="-1.45 -0.15 0" xyz="-0.81 -0.67 1.18"/>
      <geometry>
        <cylinder length="0.3" radius="0.03"/>
      </geometry>
    </collision>
    <!-- Joint -->
    <collision name="right_joint">
      <origin rpy="0 -0.6 0" xyz="0.58 -1.03 0.6"/>
      <geometry>
        <box size="0.65 0.2 0.1"/>
      </geometry>
    </collision>
    <!-- Top base -->
    <collision name="top_base">
      <origin rpy="0 0 0" xyz="0 -0 1.25"/>
      <geometry>
        <box size="1.85 1 0.1"/>
      </geometry>
    </collision>
    <inertial>
      <!-- From WAM-V spec sheet -->
      <mass value="180.0"/>
      <inertia ixx="120.0" ixy="0.0" ixz="0.0" iyy="393" iyz="0.0" izz="446.0"/>
    </inertial>
  </link>
  <link name="wamv/center_thruster_engine_link">
    <visual>
      <geometry>
        <mesh filename="package://wamv_description/models/engine/mesh/engine.dae"/>
      </geometry>
    </visual>
    <collision name="center_thruster_engine_vertical_axis_collision">
      <origin rpy="0 0 0" xyz="-0.16 0 -0.24"/>
      <geometry>
        <box size="0.2 0.15 0.83"/>
      </geometry>
    </collision>
    <collision name="center_thruster_engine_rear_end_collision">
      <origin rpy="0 0 0" xyz="-0.34 0 0.12"/>
      <geometry>
        <box size="0.12 0.15 0.12"/>
      </geometry>
    </collision>
    <inertial>
      <mass value="15"/>
      <inertia ixx="0.889245" ixy="0.0" ixz="0.0" iyy="0.911125" iyz="0.0" izz="0.078125"/>
    </inertial>
  </link>
  <link name="wamv/center_thruster_propeller_link">
    <visual>
      <geometry>
        <mesh filename="package://wamv_description/models/propeller/mesh/propeller.dae"/>
      </geometry>
    </visual>
    <collision name="center_thruster_propeller_collision">
      <origin rpy="0 1.57 0" xyz="-0.08 0 0"/>
      <geometry>
        <cylinder length="0.18" radius="0.24"/>
      </geometry>
    </collision>
    <inertial>
      <mass value="0.5"/>
      <inertia ixx="0.008545" ixy="0.0" ixz="0.0" iyy="0.008545" iyz="0.0" izz="0.0144"/>
    </inertial>
  </link>
  <joint name="wamv/center_thruster_chasis_engine_joint" type="revolute">
    <axis xyz="0 0 1"/>
    <limit effort="10" lower="-3.141592653589793" upper="3.141592653589793" velocity="10"/>
    <origin rpy="0.0 0.0 1.570796" xyz="0.0 0.0 0.318237"/>
    <parent link="wamv/base_link"/>
    <child link="wamv/center_thruster_engine_link"/>
  </joint>
  <joint name="wamv/center_thruster_engine_propeller_joint" type="continuous">
    <axis rpy="0 0 0" xyz="1 0 0"/>
    <parent link="wamv/center_thruster_engine_link"/>
    <child link="wamv/center_thruster_propeller_link"/>
    <origin rpy="0 0 0" xyz="-0.278156 0 -0.509371"/>
    <limit effort="100" velocity="100"/>
    <dynamics damping="0.05" friction="0.05"/>
  </joint>
  <link name="wamv/left_thruster_engine_link">
    <visual>
      <geometry>
        <mesh filename="package://wamv_description/models/engine/mesh/engine.dae"/>
      </geometry>
    </visual>
    <collision name="left_thruster_engine_vertical_axis_collision">
      <origin rpy="0 0 0" xyz="-0.16 0 -0.24"/>
      <geometry>
        <box size="0.2 0.15 0.83"/>
      </geometry>
    </collision>
    <collision name="left_thruster_engine_rear_end_collision">
      <origin rpy="0 0 0" xyz="-0.34 0 0.12"/>
      <geometry>
        <box size="0.12 0.15 0.12"/>
      </geometry>
    </collision>
    <inertial>
      <mass value="15"/>
      <inertia ixx="0.889245" ixy="0.0" ixz="0.0" iyy="0.911125" iyz="0.0" izz="0.078125"/>
    </inertial>
  </link>
  <link name="wamv/left_thruster_propeller_link">
    <visual>
      <geometry>
        <mesh filename="package://wamv_description/models/propeller/mesh/propeller.dae"/>
      </geometry>
    </visual>
    <collision name="left_thruster_propeller_collision">
      <origin rpy="0 1.57 0" xyz="-0.08 0 0"/>
      <geometry>
        <cylinder length="0.18" radius="0.24"/>
      </geometry>
    </collision>
    <inertial>
      <mass value="0.5"/>
      <inertia ixx="0.008545" ixy="0.0" ixz="0.0" iyy="0.008545" iyz="0.0" izz="0.0144"/>
    </inertial>
  </link>
  <joint name="wamv/left_thruster_chasis_engine_joint" type="revolute">
    <axis xyz="0 0 1"/>
    <limit effort="10" lower="-3.141592653589793" upper="3.141592653589793" velocity="10"/>
    <origin rpy="0.0 0.0 0.0" xyz="-2.373776 1.027135 0.318237"/>
    <parent link="wamv/base_link"/>
    <child link="wamv/left_thruster_engine_link"/>
  </joint>
  <joint name="wamv/left_thruster_engine_propeller_joint" type="continuous">
    <axis rpy="0 0 0" xyz="1 0 0"/>
    <parent link="wamv/left_thruster_engine_link"/>
    <child link="wamv/left_thruster_propeller_link"/>
    <origin rpy="0 0 0" xyz="-0.278156 0 -0.509371"/>
    <limit effort="100" velocity="100"/>
    <dynamics damping="0.05" friction="0.05"/>
  </joint>
  <link name="wamv/right_thruster_engine_link">
    <visual>
      <geometry>
        <mesh filename="package://wamv_description/models/engine/mesh/engine.dae"/>
      </geometry>
    </visual>
    <collision name="right_thruster_engine_vertical_axis_collision">
      <origin rpy="0 0 0" xyz="-0.16 0 -0.24"/>
      <geometry>
        <box size="0.2 0.15 0.83"/>
      </geometry>
    </collision>
    <collision name="right_thruster_engine_rear_end_collision">
      <origin rpy="0 0 0" xyz="-0.34 0 0.12"/>
      <geometry>
        <box size="0.12 0.15 0.12"/>
      </geometry>
    </collision>
    <inertial>
      <mass value="15"/>
      <inertia ixx="0.889245" ixy="0.0" ixz="0.0" iyy="0.911125" iyz="0.0" izz="0.078125"/>
    </inertial>
  </link>
  <link name="wamv/right_thruster_propeller_link">
    <visual>
      <geometry>
        <mesh filename="package://wamv_description/models/propeller/mesh/propeller.dae"/>
      </geometry>
    </visual>
    <collision name="right_thruster_propeller_collision">
      <origin rpy="0 1.57 0" xyz="-0.08 0 0"/>
      <geometry>
        <cylinder length="0.18" radius="0.24"/>
      </geometry>
    </collision>
    <inertial>
      <mass value="0.5"/>
      <inertia ixx="0.008545" ixy="0.0" ixz="0.0" iyy="0.008545" iyz="0.0" izz="0.0144"/>
    </inertial>
  </link>
  <joint name="wamv/right_thruster_chasis_engine_joint" type="revolute">
    <axis xyz="0 0 1"/>
    <limit effort="10" lower="-3.141592653589793" upper="3.141592653589793" velocity="10"/>
    <origin rpy="0.0 0.0 0.0" xyz="-2.373776 -1.027135 0.318237"/>
    <parent link="wamv/base_link"/>
    <child link="wamv/right_thruster_engine_link"/>
  </joint>
  <joint name="wamv/right_thruster_engine_propeller_joint" type="continuous">
    <axis rpy="0 0 0" xyz="1 0 0"/>
    <parent link="wamv/right_thruster_engine_link"/>
    <child link="wamv/right_thruster_propeller_link"/>
    <origin rpy="0 0 0" xyz="-0.278156 0 -0.509371"/>
    <limit effort="100" velocity="100"/>
    <dynamics damping="0.05" friction="0.05"/>
  </joint>
  <gazebo>
    <plugin filename="libusv_gazebo_thrust_plugin.so" name="wamv_gazebo_thrust">
      <cmdTimeout>1.0</cmdTimeout>
      <robotNamespace>wamv</robotNamespace>
      <thruster>
        <!-- Required Parameters -->
        <linkName>wamv/center_thruster_propeller_link</linkName>
        <propJointName>wamv/center_thruster_engine_propeller_joint</propJointName>
        <engineJointName>wamv/center_thruster_chasis_engine_joint</engineJointName>
        <cmdTopic>thrusters/center_thruster_thrust_cmd</cmdTopic>
        <angleTopic>thrusters/center_thruster_thrust_angle</angleTopic>
        <enableAngle>True</enableAngle>
        <!-- Optional Parameters -->
        <mappingType>1</mappingType>
        <maxCmd>1.0</maxCmd>
        <maxForceFwd>250.0</maxForceFwd>
        <maxForceRev>-100.0</maxForceRev>
        <maxAngle>1.5707963267948966</maxAngle>
      </thruster>
      <thruster>
        <!-- Required Parameters -->
        <linkName>wamv/left_thruster_propeller_link</linkName>
        <propJointName>wamv/left_thruster_engine_propeller_joint</propJointName>
        <engineJointName>wamv/left_thruster_chasis_engine_joint</engineJointName>
        <cmdTopic>thrusters/left_thruster_thrust_cmd</cmdTopic>
        <angleTopic>thrusters/left_thruster_thrust_angle</angleTopic>
        <enableAngle>True</enableAngle>
        <!-- Optional Parameters -->
        <mappingType>1</mappingType>
        <maxCmd>1.0</maxCmd>
        <maxForceFwd>250.0</maxForceFwd>
        <maxForceRev>-100.0</maxForceRev>
        <maxAngle>1.5707963267948966</maxAngle>
      </thruster>
      <thruster>
        <!-- Required Parameters -->
        <linkName>wamv/right_thruster_propeller_link</linkName>
        <propJointName>wamv/right_thruster_engine_propeller_joint</propJointName>
        <engineJointName>wamv/right_thruster_chasis_engine_joint</engineJointName>
        <cmdTopic>thrusters/right_thruster_thrust_cmd</cmdTopic>
        <angleTopic>thrusters/right_thruster_thrust_angle</angleTopic>
        <enableAngle>True</enableAngle>
        <!-- Optional Parameters -->
        <mappingType>1</mappingType>
        <maxCmd>1.0</maxCmd>
        <maxForceFwd>250.0</maxForceFwd>
        <maxForceRev>-100.0</maxForceRev>
        <maxAngle>1.5707963267948966</maxAngle>
      </thruster>
    </plugin>
  </gazebo>
  <!--Gazebo Plugin for simulating WAM-V dynamics-->
  <gazebo>
    <plugin filename="libusv_gazebo_dynamics_plugin.so" name="usv_dynamics_wamv_dynamics_plugin">
      <bodyName>wamv/base_link</bodyName>
      <!-- Must be same as the ocean model!-->
      <waterLevel>0</waterLevel>
      <waterDensity>997.8</waterDensity>
      <!-- Added mass -->
      <xDotU>0.0</xDotU>
      <yDotV>0.0</yDotV>
      <nDotR>0.0</nDotR>
      <!-- Linear and quadratic drag -->
      <xU>51.3</xU>
      <xUU>72.4</xUU>
      <yV>40.0</yV>
      <yVV>0.0</yVV>
      <zW>500.0</zW>
      <kP>50.0</kP>
      <mQ>50.0</mQ>
      <nR>400.0</nR>
      <nRR>0.0</nRR>
      <!-- General dimensions -->
      <!--<boatArea>2.2</boatArea>-->
      <hullRadius>0.213</hullRadius>
      <boatWidth>2.4</boatWidth>
      <boatLength>4.9</boatLength>
      <!-- Length discretization, AKA, "N" -->
      <length_n>2</length_n>
      <!-- Wave model -->
      <wave_model>ocean_waves</wave_model>
    </plugin>
  </gazebo>
  <!-- 3d lidar sensor -->
  <link name="wamv/lidar_link">
    <visual name="lidar_visual">
      <origin rpy="0 0 0" xyz="0 0 -0.035"/>
      <geometry>
        <mesh filename="package://vrx_gazebo/models/3d_lidar/mesh/3d_lidar.dae"/>
      </geometry>
    </visual>
    <collision name="lidar_collision">
      <geometry>
        <cylinder length="0.075" radius="0.055"/>
      </geometry>
    </collision>
    <inertial>
      <mass value="1"/>
      <inertia ixx="0.00109375" ixy="0" ixz="0" iyy="0.00109375" iyz="0" izz="0.00125"/>
    </inertial>
  </link>
  <!-- Sensor post -->
  <link name="wamv/lidar_post_link">
    <visual>
      <geometry>
        <cylinder length="0.2535000000000001" radius="0.0076"/>
      </geometry>
      <material name="lidar_post_material">
        <color rgba="0.0 0.0 0.0 1.0"/>
      </material>
    </visual>
    <collision name="lidar_post_collision">
      <geometry>
        <cylinder length="0.2535000000000001" radius="0.0076"/>
      </geometry>
    </collision>
    <inertial>
      <mass value="0.2281500000000001"/>
      <inertia ixx="0.0012250805141250016" ixy="0" ixz="0" iyy="0.0012250805141250016" iyz="0" izz="6.588972000000003e-06"/>
    </inertial>
  </link>
  <!-- Sensor post arm -->
  <link name="wamv/lidar_post_arm_link">
    <visual name="lidar_post_arm_visual">
      <origin rpy="-1.0471975511965976 0 -1.5707963267948966" xyz="-0.038 0 -0.003"/>
      <geometry>
        <mesh filename="package://vrx_gazebo/models/sensor_post/mesh/sensor_post_arm.dae"/>
      </geometry>
    </visual>
    <collision name="lidar_post_arm_collision">
      <origin rpy="-1.2042771838760873 0 -1.5707963267948966" xyz="0 0 0"/>
      <geometry>
        <cylinder length="0.065" radius="0.008"/>
      </geometry>
    </collision>
    <inertial>
      <origin rpy="-1.2042771838760873 0 -1.5707963267948966" xyz="0 0 0"/>
      <mass value="0.1"/>
      <inertia ixx="0.00003680833" ixy="0" ixz="0" iyy="0.00003680833" iyz="0" izz="0.00000320000"/>
    </inertial>
  </link>
  <joint name="wamv/base_to_lidar_post_joint" type="fixed">
    <origin rpy="0 0 0" xyz="0.6299999999999999 0.0 1.4232500000000001"/>
    <parent link="wamv/base_link"/>
    <child link="wamv/lidar_post_link"/>
  </joint>
  <!-- Sensor post to sensor post arm joint -->
  <joint name="wamv/lidar_post_to_lidar_post_arm_joint" type="fixed">
    <origin rpy="0 0 0" xyz="0.03 0 0.12674999999999997"/>
    <parent link="wamv/lidar_post_link"/>
    <child link="wamv/lidar_post_arm_link"/>
  </joint>
  <!-- Sensor post arm to lidar joint -->
  <joint name="wamv/lidar_post_arm_to_lidar_joint" type="fixed">
    <origin rpy="0.0 0.1 0.0" xyz="0.04 0 0.05"/>
    <parent link="wamv/lidar_post_arm_link"/>
    <child link="wamv/lidar_link"/>
  </joint>
  <gazebo reference="wamv/lidar_link">
    <sensor name="lidar_sensor" type="gpu_ray">
      <update_rate>10</update_rate>
      <ray>
        <scan>
          <horizontal>
            <samples>18750.0</samples>
            <resolution>0.1</resolution>
            <min_angle>-3.141592653589793</min_angle>
            <max_angle>3.141592653589793</max_angle>
          </horizontal>
          <vertical>
            <samples>16</samples>
            <resolution>1</resolution>
            <min_angle>-0.2617993877991494</min_angle>
            <max_angle>0.2617993877991494</max_angle>
          </vertical>
        </scan>
        <range>
          <min>0.1</min>
          <max>130</max>
        </range>
        <noise>
          <type>gaussian</type>
          <mean>0.0</mean>
          <stddev>0.01</stddev>
        </noise>
      </ray>
      <plugin filename="libgazebo_ros_velodyne_gpu_laser.so" name="lidar_plugin">
        <topicName>wamv/sensors/lidars/lidar/points</topicName>
        <frameName>wamv/lidar_link</frameName>
        <min_intensity>0</min_intensity>
      </plugin>
    </sensor>
  </gazebo>
  <!-- Set color of post -->
  <gazebo reference="wamv/lidar_post_link">
    <material>Gazebo/Black</material>
  </gazebo>
  <!--specs for 16 beam lidar are implemented by default.
          See wamv_3d_lidar for those-->
  <!-- Monocular Camera -->
  <link name="wamv/camera_link">
    <visual name="camera_visual">
      <origin rpy="0 0 1.5707963267948966" xyz="-0.033 0 0"/>
      <geometry>
        <mesh filename="package://vrx_gazebo/models/mono_camera/mesh/mono_camera.dae"/>
      </geometry>
    </visual>
    <collision name="camera_lens_collision">
      <origin rpy="0 1.5707963267948966 0" xyz="0.018 0 0"/>
      <geometry>
        <cylinder length="0.042" radius="0.015"/>
      </geometry>
    </collision>
    <collision name="camera_box_collision">
      <origin rpy="0 0 0" xyz="-0.0205 0 0"/>
      <geometry>
        <box size="0.036 0.03 0.03"/>
      </geometry>
    </collision>
    <!-- Model inertia as box with <size>0.078 0.03 0.03</size> -->
    <inertial>
      <mass value="0.3"/>
      <inertia ixx="0.0000450" ixy="0" ixz="0" iyy="0.0001746" iyz="0" izz="0.0001746"/>
    </inertial>
  </link>
  <!-- Define a link for the optical frame.  This will match the sensor frame and
         be oriented in the camera convention. -->
  <link name="wamv/camera_link_optical">
    </link>
  <!-- Sensor post -->
  <link name="wamv/camera_post_link">
    <visual>
      <geometry>
        <cylinder length="0.17650000000000002" radius="0.0076"/>
      </geometry>
      <material name="camera_post_material">
        <color rgba="0.0 0.0 0.0 1.0"/>
      </material>
    </visual>
    <collision name="camera_post_collision">
      <geometry>
        <cylinder length="0.17650000000000002" radius="0.0076"/>
      </geometry>
    </collision>
    <inertial>
      <mass value="0.15885000000000002"/>
      <inertia ixx="0.0004146717033750001" ixy="0" ixz="0" iyy="0.0004146717033750001" iyz="0" izz="4.5875880000000004e-06"/>
    </inertial>
  </link>
  <!-- Sensor post arm -->
  <link name="wamv/camera_post_arm_link">
    <visual name="camera_post_arm_visual">
      <origin rpy="-1.0471975511965976 0 -1.5707963267948966" xyz="-0.038 0 -0.003"/>
      <geometry>
        <mesh filename="package://vrx_gazebo/models/sensor_post/mesh/sensor_post_arm.dae"/>
      </geometry>
    </visual>
    <collision name="camera_post_arm_collision">
      <origin rpy="-1.2042771838760873 0 -1.5707963267948966" xyz="0 0 0"/>
      <geometry>
        <cylinder length="0.065" radius="0.008"/>
      </geometry>
    </collision>
    <inertial>
      <origin rpy="-1.2042771838760873 0 -1.5707963267948966" xyz="0 0 0"/>
      <mass value="0.1"/>
      <inertia ixx="0.00003680833" ixy="0" ixz="0" iyy="0.00003680833" iyz="0" izz="0.00000320000"/>
    </inertial>
  </link>
  <joint name="wamv/base_to_camera_post_joint" type="fixed">
    <origin rpy="0 0 0" xyz="0.7 0.0 1.38475"/>
    <parent link="wamv/base_link"/>
    <child link="wamv/camera_post_link"/>
  </joint>
  <!-- Sensor post to sensor post arm joint -->
  <joint name="wamv/camera_post_to_camera_post_arm_joint" type="fixed">
    <origin rpy="0 0 0" xyz="0.03 0 0.08825000000000008"/>
    <parent link="wamv/camera_post_link"/>
    <child link="wamv/camera_post_arm_link"/>
  </joint>
  <!-- Sensor post arm to camera joint -->
  <joint name="wamv/camera_post_arm_to_camera_joint" type="fixed">
    <origin rpy="0.0 0.2617993877991494 0.0" xyz="0.02 0 0.027"/>
    <parent link="wamv/camera_post_arm_link"/>
    <child link="wamv/camera_link"/>
  </joint>
  <!-- Camera to optical frame joint.  This is oriented to convert between ENU
         and camera conventions -->
  <joint name="wamv/camera_to_camera_link_optical_joint" type="fixed">
    <origin rpy="-1.5707963267948966 0 -1.5707963267948966" xyz="0 0 0"/>
    <parent link="wamv/camera_link"/>
    <child link="wamv/camera_link_optical"/>
  </joint>
  <!-- Gazebo camera setup -->
  <gazebo reference="wamv/camera_link">
    <sensor name="camera_sensor" type="camera">
      <update_rate>30.0</update_rate>
      <camera name="camera_camera">
        <horizontal_fov>1.3962634</horizontal_fov>
        <image>
          <width>1280</width>
          <height>720</height>
          <format>R8G8B8</format>
        </image>
        <clip>
          <near>0.05</near>
          <far>300</far>
        </clip>
        <noise>
          <type>gaussian</type>
          <!-- Noise is sampled independently per pixel on each frame.
                 That pixel's noise value is added to each of its color
                 channels, which at that point lie in the range [0,1]. -->
          <mean>0.0</mean>
          <stddev>0.007</stddev>
        </noise>
      </camera>
      <plugin filename="libgazebo_ros_camera.so" name="camera_plugin_camera">
        <alwaysOn>true</alwaysOn>
        <updateRate>0.0</updateRate>
        <cameraName>wamv/sensors/cameras/camera</cameraName>
        <imageTopicName>image_raw</imageTopicName>
        <cameraInfoTopicName>camera_info</cameraInfoTopicName>
        <frameName>wamv/camera_link_optical</frameName>
        <hackBaseline>0.07</hackBaseline>
        <distortionK1>0.0</distortionK1>
        <distortionK2>0.0</distortionK2>
        <distortionK3>0.0</distortionK3>
        <distortionT1>0.0</distortionT1>
        <distortionT2>0.0</distortionT2>
      </plugin>
    </sensor>
  </gazebo>
  <!-- Set color of post -->
  <gazebo reference="wamv/camera_post_link">
    <material>Gazebo/Black</material>
  </gazebo>
  <link name="wamv/gps_link">
    <visual name="gps_visual">
      <geometry>
        <mesh filename="package://wamv_gazebo/models/gps/mesh/gps.dae"/>
      </geometry>
    </visual>
    <collision name="gps_collision_base">
      <origin rpy="0 0 0" xyz="0 0 0.025"/>
      <geometry>
        <cylinder length="0.05" radius="0.015"/>
      </geometry>
    </collision>
    <collision name="gps_collision_antenna">
      <origin rpy="0 0 0" xyz="0 0 0.11"/>
      <geometry>
        <cylinder length="0.1" radius="0.15"/>
      </geometry>
    </collision>
    <inertial>
      <mass value="1"/>
      <inertia ixx="0.006458" ixy="0.0" ixz="0.0" iyy="0.006458" iyz="0.0" izz="0.01125"/>
    </inertial>
  </link>
  <joint name="wamv/gps_joint" type="revolute">
    <axis xyz="0 0 1"/>
    <limit effort="1000.0" lower="0.0" upper="0" velocity="0"/>
    <origin rpy="0.0 0.0 0.0" xyz="-0.85 0.0 1.3"/>
    <parent link="wamv/base_link"/>
    <child link="wamv/gps_link"/>
  </joint>
  <gazebo>
    <plugin filename="libhector_gazebo_ros_gps.so" name="gps_plugin_gps">
      <updateRate>15</updateRate>
      <alwaysOn>true</alwaysOn>
      <bodyName>wamv/gps_link</bodyName>
      <!-- Manually prepend namespace to tf frame. -->
      <frameId>wamv/gps_link</frameId>
      <topicName>wamv/sensors/gps/gps/fix</topicName>
      <!-- Note that the hector_gazebo_ros_gps plugin uses NWU coordinates
             for reporting velocities.  This may cause problems if localization
             requires velocity in ENU.
             See Issue #64 in VRX project for details
             https://bitbucket.org/osrf/vrx/issues/64 -->
      <velocityTopicName>wamv/sensors/gps/gps/fix_velocity</velocityTopicName>
      <!-- Tell the plugin to use the spherical_coordiantes parameters
	     from SDF.
	     https://github.com/tu-darmstadt-ros-pkg/hector_gazebo/blob/melodic-devel/hector_gazebo_plugins/src/gazebo_ros_gps.cpp#L101
	-->
      <useWorldSphericalCoordinates>true</useWorldSphericalCoordinates>
      <offset>0.0 0.0 0.0</offset>
      <drift>0.0 0.0 0.0</drift>
      <gaussianNoise>0 0 0</gaussianNoise>
      <velocityOffset>0.0 0.0 0.0</velocityOffset>
      <velocityDrift>0.0 0.0 0.0</velocityDrift>
      <velocityGaussianNoise>0.0 0.0 0.0</velocityGaussianNoise>
    </plugin>
  </gazebo>
  <link name="wamv/imu_link">
    <visual name="imu_visual">
      &gt;
        
      <geometry>
        <box size="0.05 0.025 0.005"/>
      </geometry>
      <material name="imu_visual_material">
        <color rgba="1.0 0.0 00 1.0"/>
      </material>
    </visual>
    <inertial>
      <mass value="0.1"/>
      <inertia ixx="0.000083" ixy="0.0" ixz="0.0" iyy="0.000083" iyz="0.0" izz="0.0125"/>
    </inertial>
  </link>
  <joint name="wamv/imu_joint" type="revolute">
    <axis xyz="0 0 1"/>
    <limit effort="1000.0" lower="0.0" upper="0" velocity="0"/>
    <origin rpy="0.0 0.0 0.0" xyz="-0.8 0.0 1.3"/>
    <parent link="wamv/base_link"/>
    <child link="wamv/imu_link"/>
  </joint>
  <gazebo>
    <plugin filename="libhector_gazebo_ros_imu.so" name="imu_plugin_imu">
      <updateRate>15</updateRate>
      <bodyName>wamv/imu_link</bodyName>
      <topicName>wamv/sensors/imu/imu/data</topicName>
      <serviceName>wamv/sensors/imu_service</serviceName>
      <!-- Manually prepend namespace to tf frame. -->
      <frameId>wamv/imu_link</frameId>
      <alwaysOn>true</alwaysOn>
      <accelOffset>0.0 0.0 0.0</accelOffset>
      <accelDrift>0.0 0.0 0.0</accelDrift>
      <accelDriftFrequency>0.00027 0.00027 0.000027</accelDriftFrequency>
      <accelGaussianNoise>0.0 0.0 0.0</accelGaussianNoise>
      <rateOffset>0.0 0.0 0.0</rateOffset>
      <rateDrift>0.0 0.0 0.0</rateDrift>
      <rateDriftFrequency>0.00027 0.00027 0.000027</rateDriftFrequency>
      <rateGaussianNoise>0.0 0.0 0.0</rateGaussianNoise>
      <yawOffset>0.0</yawOffset>
      <yawDrift>0.0</yawDrift>
      <yawDriftFrequency>0.00027</yawDriftFrequency>
      <yawGaussianNoise>0.0</yawGaussianNoise>
    </plugin>
  </gazebo>
  <link name="wamv/ball_shooter_base_link">
    <visual name="ball_shooter_base_visual">
      <origin rpy="0 0 0" xyz="0 0 0"/>
      <geometry>
        <mesh filename="package://vrx_gazebo/models/ball_shooter/meshes/ball_shooter_base.dae"/>
      </geometry>
    </visual>
    <inertial>
      <origin rpy="0 0 0" xyz="-0.02 0 0.05"/>
      <mass value="0.5"/>
      <inertia ixx="0.00083" ixy="0.0" ixz="0.0" iyy="0.00052083" iyz="0.0" izz="0.00052083"/>
    </inertial>
  </link>
  <link name="wamv/ball_shooter_launcher_link">
    <visual name="ball_shooter_launcher_visual">
      <!-- The cylinder has a -15deg pitch. We compensate for that here.
             That way, if the user passes a 0 deg rotation the cylinder will
             be parallel to the ground -->
      <!-- <origin xyz="-0.0204 0 0.107877" rpy="0 0.261799 0" /> -->
      <origin rpy="0 0.261799 0" xyz="0 0 0"/>
      <geometry>
        <mesh filename="package://vrx_gazebo/models/ball_shooter/meshes/ball_shooter_launcher.dae"/>
      </geometry>
    </visual>
    <!-- Uncomment to see the pose where the ball is teleported -->
    <!-- <visual name="${name}_visual_ball">
        <origin xyz="0.14 0 0" rpy="0 0 0" />
        <geometry>
          <sphere radius="0.0285"/>
        </geometry>
      </visual> -->
    <collision name="ball_shooter_collision">
      <origin rpy="0 0.261799 0" xyz="0 0 0"/>
      <geometry>
        <box size="0.3 0.3 0.2"/>
      </geometry>
    </collision>
    <inertial>
      <origin rpy="0 -1.5708 0" xyz="0 0 0"/>
      <mass value="0.5"/>
      <inertia ixx="0.001779167" ixy="0.0" ixz="0.0" iyy="0.001779167" iyz="0.0" izz="0.000225"/>
    </inertial>
  </link>
  <joint name="wamv/ball_shooter_base_joint" type="revolute">
    <axis xyz="0 0 1"/>
    <limit effort="1000.0" lower="0.0" upper="0" velocity="0"/>
    <origin rpy="0 0 0.0" xyz="0.55 0.1 1.3"/>
    <parent link="wamv/base_link"/>
    <child link="wamv/ball_shooter_base_link"/>
  </joint>
  <joint name="wamv/ball_shooter_launcher_joint" type="revolute">
    <axis xyz="0 0 1"/>
    <limit effort="1000.0" lower="0.0" upper="0" velocity="0"/>
    <origin rpy="0 -0.7853981633974483 0" xyz="-0.0204 0 0.107877"/>
    <parent link="wamv/ball_shooter_base_link"/>
    <child link="wamv/ball_shooter_launcher_link"/>
  </joint>
  <gazebo>
    <plugin filename="libball_shooter_plugin.so" name="ball_shooter_plugin">
      <projectile>
        <model_name>blue_projectile</model_name>
        <link_name>link</link_name>
        <frame>wamv/ball_shooter_launcher_link</frame>
        <pose>0.14 0 0 0 0 0</pose>
      </projectile>
      <num_shots>4</num_shots>
      <shot_force>300</shot_force>
      <topic>wamv/shooters/ball_shooter/fire</topic>
    </plugin>
  </gazebo>
  <link name="wamv/pinger">
    <visual>
      <origin rpy="0 0 0" xyz="0 0 0"/>
      <geometry>
        <box size="0.1 0.1 0.1"/>
      </geometry>
    </visual>
    <collision name="pinger_collision">
      <origin rpy="0 0 0" xyz="0 0 0"/>
      <geometry>
        <box size="0.1 0.1 0.1"/>
      </geometry>
    </collision>
  </link>
  <joint name="wamv/pinger_pinger_joint" type="fixed">
    <origin rpy="0 0 0" xyz="1.0 0 -1.0"/>
    <parent link="wamv/base_link"/>
    <child link="wamv/pinger"/>
  </joint>
  <gazebo>
    <plugin filename="libusv_gazebo_acoustic_pinger_plugin.so" name="pinger_plugin">
      <frameId>wamv/pinger</frameId>
      <topicName>wamv/sensors/pingers/pinger/range_bearing</topicName>
      <setPositionTopicName>wamv/sensors/pingers/pinger/set_pinger_position</setPositionTopicName>
      <rangeNoise>
        <noise>
          <type>gaussian</type>
          <mean>0.0</mean>
          <stddev>3.0</stddev>
        </noise>
      </rangeNoise>
      <bearingNoise>
        <noise>
          <type>gaussian</type>
          <mean>0.0</mean>
          <stddev>0.01</stddev>
        </noise>
      </bearingNoise>
      <elevationNoise>
        <noise>
          <type>gaussian</type>
          <mean>0.0</mean>
          <stddev>0.01</stddev>
        </noise>
      </elevationNoise>
    </plugin>
  </gazebo>
  <link name="wamv/cpu_cases_link">
    <visual name="cpu_cases_visual">
      <origin rpy="0 0 0" xyz="0.073 0 -1.53"/>
      <geometry>
        <mesh filename="package://vrx_gazebo/models/cpu_cases/mesh/cpu_cases.dae"/>
      </geometry>
    </visual>
    <collision name="cpu_case_1_collision">
      <origin rpy="0 0 0" xyz="0.185 0 0"/>
      <geometry>
        <box size="0.595 0.83 0.47"/>
      </geometry>
    </collision>
    <collision name="cpu_case_2_collision">
      <origin rpy="0 0 0" xyz="-0.3 0 -0.092"/>
      <geometry>
        <box size="0.375 0.64 0.28"/>
      </geometry>
    </collision>
    <inertial>
      <mass value="20"/>
      <inertia ixx="1.51633333333333" ixy="0" ixz="0" iyy="1.93633333333333" iyz="0" izz="2.71633333333333"/>
    </inertial>
  </link>
  <joint name="wamv/chasis_cpu_cases_joint" type="fixed">
    <origin rpy="0 0 0" xyz="-0.15 0 1.53"/>
    <parent link="wamv/base_link"/>
    <child link="wamv/cpu_cases_link"/>
  </joint>
</robot>
